Workbook

Sheet 1 Read Me
A1: Item | B1: Detail
A2: Purpose | B2: Internal and investor-facing. This is the basis for a full financial model, not the full model. It establishes unit economics, the capacity constraint, three-year shape and the sensitivities that matter. A complete model would add monthly cohorts, cash timing, working capital and a balance sheet.
A3: Currency and tax | B3: All figures CAD and exclusive of GST, HST and QST. Tax is collected and remitted, it is not revenue.
A4: Relationship to the pricing model | B4: Every price, unit cost and redemption assumption is carried forward unchanged from the approved membership pricing model. Nothing has been re-rounded. If a driver changes there, change it here.
A5: How to use it | B5: Tab 2 Drivers is the only place to edit. Every other tab is formula-driven off it. Blue cells are editable inputs, black cells are calculated. Change a driver and the whole model moves.
A6: The three findings | B6: 1. Each city chapter has a hard membership ceiling of roughly 35 paying members at quarterly cadence. Growth comes from more cities and more evenings, not more members per city. 2. Membership is under 30 percent of revenue at every stage. Sponsorship is around half. Membership qualifies the room; sponsorship monetises it. 3. The dinner programme only clears its cost floor when sponsored or partner-hosted. That is an operating rule, not a preference.
A7: What is deliberately conservative | B7: Dinner sponsor attach starts at 60 percent, not 100. Summit revenue is a single blended assumption pending a seat-by-seat build. Founder compensation appears from year two. No revenue is booked for trust-safe services in phase three.
A8: What is deliberately aggressive | B8: Retention has no history behind it. Chief tier volumes assume a partner ladder that does not exist yet. Summit ticket and booth revenue in years two and three is the least evidenced line in the model.
A9: Not financial advice | B9: Assumption-based planning model. Validate pricing, tax treatment and any figure shown to a third party with a Canadian accountant before it is relied upon.

Sheet 2 Drivers
A1: Driver | B1: Value | C1: Note
A3: UNIT COSTS (carried from the approved pricing model)
A4: Dinner seat cost, restaurant format | B4: 105 | C4: TO and VAN benchmark. 3 courses, venue minimum, service.
A5: Dinner seat cost, partner-hosted format | B5: 55 | C5: Donated venue, catering only. The cheapest seat in the model.
A6: Share of dinners partner-hosted | B6: 0.5 | C6: THE SINGLE BIGGEST COST LEVER. See tab 9 sensitivity.
A7: Blended dinner seat cost | B7: =B4*(1-B6)+B5*B6 -> 80 | C7: Calculated.
A8: Summit cost per attendee | B8: 200 | C8: Venue, AV, catering, staffing at 150 to 450 attendees.
A9: Exhibitor booth servicing cost | B9: 400 | C9: Floor space, table, power, listing.
A10: Welcome kit, standard | B10: 45 | C10: Resident and Attending.
A11: Welcome kit, Chief | B11: 120 | C11: Full kit plus printed materials.
A12: Platform and ops per member per year | B12: 25 | C12: Supabase, Vercel, Resend. Applied to guests as well as paying members.
A13: Cohort session cost | B13: 150 | C13: Editing and hosting. Fixed, not per member.
A14: Cohort sessions per year | B14: 8
A16: PUBLIC RATES
A17: Public dinner ticket | B17: 70 | C17: Set below true cost on purpose. Sponsors close the gap.
A18: Public summit day pass | B18: 395
A19: Public exhibitor booth | B19: 2500
A21: TIER PRICES
A22: Resident, annual | B22: 290 | C22: Decoy. Priced at roughly four dinner tickets.
A23: Attending, annual | B23: 790 | C23: HERO. Captures 19.4 percent of quantified value.
A24: Chief, annual | B24: 2950 | C24: Anchor. 3.7x the hero.
A26: TYPICAL REDEMPTION (what a member actually uses)
A27: Resident, home dinners attended | B27: 2.3 | C27: Of 4 available.
A28: Attending, home dinners | B28: 2.3
A29: Attending, away dinners | B29: 0.6 | C29: Of 2 included.
A30: Attending, summit pass used | B30: 0.7
A31: Chief, dinners attended nationally | B31: 6 | C31: Of up to 20 available. Travel is the natural cap.
A32: Chief, summit passes used | B32: 1.5 | C32: Of 2.
A33: Chief, exhibitor booth used | B33: 1
A35: RETENTION AND ACQUISITION
A36: Resident annual retention | B36: 0.65 | C36: ASSUMPTION. No history. The weakest number in the model.
A37: Attending annual retention | B37: 0.75 | C37: ASSUMPTION.
A38: Chief annual retention | B38: 0.85 | C38: ASSUMPTION.
A39: CAC, Resident | B39: 80 | C39: Mostly organic: content, keynote, nomination flow.
A40: CAC, Attending | B40: 250
A41: CAC, Chief | B41: 900 | C41: Includes founder selling time.
A42: Blended CAC | B42: 220 | C42: Used in the three-year build.
A44: CAPACITY (the binding constraint)
A45: Seats per dinner | B45: 40 | C45: The format. Changing this changes the product.
A46: Paying-member share of seats | B46: 0.5 | C46: 1:1 builders to validators. Composition rule, not a preference.
...

Sheet 3 Unit Economics
A1: Tier | B1: Annual fee | C1: Dinner cost | D1: Summit cost | E1: Kit + platform | F1: Total cost, UNSPONSORED | G1: Contribution, UNSPONSORED | H1: Total cost, SPONSORED | I1: Contribution, SPONSORED | J1: What this tells you
A2: Guest | B2: 0 | C2: ='2 Drivers'!$B$48*'2 Drivers'!$B$7 -> 184 | D2: 0 | E2: ='2 Drivers'!$B$12 -> 25 | F2: =C2+D2+E2 -> 209 | G2: =IF(B2=0,"n/a, this is the magnet",B2-F2) -> n/a, this is the magnet | H2: =D2+E2 -> 25 | I2: =IF(B2=0,"n/a",B2-H2) -> n/a | J2: This is the investment that makes every other tier sellable. A guest costs about $209 a year and is the reason a partner pays $15,000.
A3: Resident | B3: ='2 Drivers'!$B$22 -> 290 | C3: ='2 Drivers'!$B$27*'2 Drivers'!$B$7 -> 184 | D3: 0 | E3: ='2 Drivers'!$B$10+'2 Drivers'!$B$12 -> 70 | F3: =C3+D3+E3 -> 254 | G3: =IF(B3=0,"n/a, this is the magnet",B3-F3) -> 36 | H3: =D3+E3 -> 70 | I3: =IF(B3=0,"n/a",B3-H3) -> 220 | J3: Positive only when dinners are sponsored. Unsponsored, Resident is a break-even tier at best.
A4: Attending | B4: ='2 Drivers'!$B$23 -> 790 | C4: =('2 Drivers'!$B$28+'2 Drivers'!$B$29)*'2 Drivers'!$B$7 -> 232 | D4: ='2 Drivers'!$B$30*'2 Drivers'!$B$8 -> 140 | E4: ='2 Drivers'!$B$10+'2 Drivers'!$B$12 -> 70 | F4: =C4+D4+E4 -> 442 | G4: =IF(B4=0,"n/a, this is the magnet",B4-F4) -> 348 | H4: =D4+E4 -> 210 | I4: =IF(B4=0,"n/a",B4-H4) -> 580 | J4: The hero. Roughly 73 percent contribution when sponsored, and it carries the summit.
A5: Chief | B5: ='2 Drivers'!$B$24 -> 2950 | C5: ='2 Drivers'!$B$31*'2 Drivers'!$B$7 -> 480 | D5: ='2 Drivers'!$B$32*'2 Drivers'!$B$8 -> 300 | E5: ='2 Drivers'!$B$11+'2 Drivers'!$B$12+'2 Drivers'!$B$9*'2 Drivers'!$B$33 -> 545 | F5: =C5+D5+E5 -> 1325 | G5: =IF(B5=0,"n/a, this is the magnet",B5-F5) -> 1625 | H5: =D5+E5 -> 845 | I5: =IF(B5=0,"n/a",B5-H5) -> 2105 | J5: Highest absolute contribution per member by a wide margin. Twelve Chiefs contribute more than eighty Residents.
A7: Contribution margin, sponsored | B7: =I3/B3 -> 0.75862069 | C7: =I4/B4 -> 0.73417722 | D7: =I5/B5 -> 0.71355932
A9: Read the two right-hand columns. With sponsored or partner-hosted dinners every paid tier carries healthy contribution. Guest is not a loss line, it is customer acquisition cost for the sponsorship business.

Sheet 4 LTV, CAC & Payback
A1: Tier | B1: Annual contribution (sponsored) | C1: Annual retention | D1: Expected lifetime, years | E1: LTV | F1: CAC | G1: LTV to CAC | H1: Read
A2: Resident | B2: ='3 Unit Economics'!I3 -> 220 | C2: ='2 Drivers'!$B$36 -> 0.65 | D2: =1/(1-C2) -> 2.8571429 | E2: =B2*D2 -> 628.57143 | F2: ='2 Drivers'!$B$39 -> 80 | G2: =E2/F2 -> 7.8571429 | H2: Volume tier. Pays back inside the first year and funds composition.
A3: Attending | B3: ='3 Unit Economics'!I4 -> 580 | C3: ='2 Drivers'!$B$37 -> 0.75 | D3: =1/(1-C3) -> 4 | E3: =B3*D3 -> 2320 | F3: ='2 Drivers'!$B$40 -> 250 | G3: =E3/F3 -> 9.28 | H3: The tier to push. Strong ratio and the longest payback runway of the three.
A4: Chief | B4: ='3 Unit Economics'!I5 -> 2105 | C4: ='2 Drivers'!$B$38 -> 0.85 | D4: =1/(1-C4) -> 6.6666667 | E4: =B4*D4 -> 14033.333 | F4: ='2 Drivers'!$B$41 -> 900 | G4: =E4/F4 -> 15.592593 | H4: Highest LTV by an order of magnitude, and the natural feeder into category partnership.
A6: Payback period, months | B6: =F2/B2*12 -> 4.3636364 | C6: =F3/B3*12 -> 5.1724138 | D6: =F4/B4*12 -> 5.1306413
A8: Retention rates carry no history and are the softest inputs in the whole model. Treat every figure on this tab as directional until two renewal cycles have run. The honest investor line is that LTV is a projection, not a measurement.
A10: A ratio above 3 is generally considered healthy. All three tiers clear it comfortably on these assumptions, which is a signal that either the assumptions are optimistic or the pricing is conservative. Given the capacity ceiling in tab 6, conservative pricing is the more likely explanation, and there is room to raise Attending at the first renewal.

Sheet 5 Event P&L
A1: Line | B1: One dinner | C1: One summit | D1: Note
A2: Attendees / seats | B2: ='2 Drivers'!$B$45 -> 40 | C2: 380 | D2: Dinner is fixed at 40 by format. Summit shown at the year-two assumption.
A3: Delivery cost per head | B3: ='2 Drivers'!$B$7 -> 80 | C3: ='2 Drivers'!$B$8 -> 200 | D3: Blended for the dinner, all-in for the summit.
A4: Total delivery cost | B4: =B2*B3 -> 3200 | C4: =C2*C3 -> 76000
A5: Sponsor revenue | B5: ='2 Drivers'!$B$51 -> 4000 | C5: ='2 Drivers'!$B$54 -> 25000 | D5: Per-dinner sponsor at the low end of the band. One summit sponsor.
A6: Ticket and booth revenue | B6: 400 | C6: 45000 | D6: ASSUMPTION. Dinner: a few non-member seats at $70. Summit: mixed public, member and exhibitor revenue.
A7: Total event revenue | B7: =B5+B6 -> 4400 | C7: =C5+C6 -> 70000
A8: Event contribution | B8: =B7-B4 -> 1200 | C8: =C7-C4 -> -6000 | D8: Before any membership revenue is counted.
A9: Contribution margin | B9: =B8/B7 -> 0.27272727 | C9: =C8/C7 -> -0.085714286
A10: Break-even sponsor level, no ticket revenue | B10: =B4 -> 3200 | C10: =C4-C6 -> 31000 | D10: The cheque size at which the event costs nothing.
A12: A dinner is contribution positive on a single low-band sponsor before a member has paid anything. That is the point of the whole structure: the events are funded by sponsorship, and membership revenue drops almost entirely to contribution.
A14: The summit is the opposite shape. It carries real delivery cost and depends on ticket and booth revenue, which is the least evidenced line in this model. Build it seat by seat before committing to a venue.

Sheet 6 Capacity & Ceiling
A1: Line | B1: Value | F1: Note
A2: Seats per dinner | B2: ='2 Drivers'!$B$45 -> 40 | F2: The format. Changing this changes the product.
A3: Paying-member share of seats | B3: ='2 Drivers'!$B$46 -> 0.5 | F3: Composition rule. Half the room is hosted guests.
A4: Paying seats per dinner | B4: =B2*B3 -> 20 | F4: Calculated.
A5: Average home dinners per paying member | B5: ='2 Drivers'!$B$48 -> 2.3 | F5: Typical redemption, not entitlement.
A7: THE CHAPTER CEILING AT DIFFERENT CADENCES
A8: Dinners per city per year | B8: Paying seat-slots per year | C8: Ceiling on paying members per chapter | D8: Membership revenue per chapter | E8: 5 chapters at this cadence | F8: Note
A9: 4 | B9: =A9*$B$4 -> 80 | C9: =B9/$B$5 -> 34.782609 | D9: =C9*784.2 -> 27276.522 | E9: =D9*5 -> 136382.61 | F9: Quarterly. The launch cadence.
A10: 6 | B10: =A10*$B$4 -> 120 | C10: =B10/$B$5 -> 52.173913 | D10: =C10*784.2 -> 40914.783 | E10: =D10*5 -> 204573.91 | F10: Every two months. The first real growth lever.
A11: 8 | B11: =A11*$B$4 -> 160 | C11: =B11/$B$5 -> 69.565217 | D11: =C11*784.2 -> 54553.043 | E11: =D11*5 -> 272765.22 | F11: Six weekly. Operationally heavy for one person.
A12: 12 | B12: =A12*$B$4 -> 240 | C12: =B12/$B$5 -> 104.34783 | D12: =C12*784.2 -> 81829.565 | E12: =D12*5 -> 409147.83 | F12: Monthly. Requires a chapter host per city.
A14: Blended ARPU used above | B14: 784.2 | F14: Assumes a 53 / 35 / 12 split across Resident, Attending and Chief.
A16: THE FINDING. At quarterly cadence a city chapter tops out near 35 paying members. Five chapters cap membership revenue around $137,000 a year. That number is not a failure of pricing, it is the arithmetic of a 40 seat room with half its seats reserved for guests who never pay.
A18: Three consequences follow. First, growth comes from more cities and more evenings per city, not from selling harder into an existing chapter. Second, membership can never be the main revenue line, which is exactly why the sponsorship architecture exists. Third, a waitlist is a feature: it is the proof of scarcity that prices the sponsorship.
A20: The lever to watch is cadence. Moving Toronto alone from four dinners to eight roughly doubles that chapter without adding a city, at the cost of operating load. Model a chapter host before doing it.

Sheet 7 Three-Year Build
A1: Line | B1: Year 1 | C1: Year 2 | D1: Year 3 | E1: Note
A2: PROGRAMME
A3: Chapters live | B3: 3 | C3: 5 | D3: 5 | E3: Toronto, Montreal, Vancouver first. Ottawa and Calgary in year two.
A4: Dinners in the year | B4: 12 | C4: 20 | D4: 24 | E4: Year three lifts Toronto and Vancouver to six.
A5: Summits | B5: 1 | C5: 2 | D5: 2 | E5: Toronto only in year one.
A6: MEMBERS
A7: Guest members (free) | B7: 90 | C7: 200 | D7: 280 | E7: Target 1.5 guests per paying member to hold composition.
A8: Resident | B8: 45 | C8: 80 | D8: 95
A9: Attending | B9: 30 | C9: 52 | D9: 64 | E9: The tier to push.
A10: Chief | B10: 8 | C10: 18 | D10: 21
A11: Total paying members | B11: =SUM(B8:B10) -> 83 | C11: =SUM(C8:C10) -> 150 | D11: =SUM(D8:D10) -> 180
A12: Seat capacity ceiling | B12: =B4*'2 Drivers'!$B$47/'2 Drivers'!$B$48 -> 104.34783 | C12: =C4*'2 Drivers'!$B$47/'2 Drivers'!$B$48 -> 173.91304 | D12: =D4*'2 Drivers'!$B$47/'2 Drivers'!$B$48 -> 208.69565 | E12: From tab 6. This is the hard limit.
A13: Capacity utilisation | B13: =B11/B12 -> 0.79541667 | C13: =C11/C12 -> 0.8625 | D13: =D11/D12 -> 0.8625 | E13: Above 90 percent means a waitlist, which is good, and oversubscription, which is not.
A14: REVENUE
A15: Membership | B15: =B8*'2 Drivers'!$B$22+B9*'2 Drivers'!$B$23+B10*'2 Drivers'!$B$24 -> 60350 | C15: =C8*'2 Drivers'!$B$22+C9*'2 Drivers'!$B$23+C10*'2 Drivers'!$B$24 -> 117380 | D15: =D8*'2 Drivers'!$B$22+D9*'2 Drivers'!$B$23+D10*'2 Drivers'!$B$24 -> 140060
A16: Dinner sponsor attach rate | B16: 0.6 | C16: 0.8 | D16: 0.9 | E16: Share of dinners with a sponsor or donated venue.
A17: Dinner sponsorship | B17: =B4*'2 Drivers'!$B$51*B16 -> 28800 | C17: =C4*'2 Drivers'!$B$51*C16 -> 64000 | D17: =D4*'2 Drivers'!$B$51*D16 -> 86400
A18: Anchor partners | B18: 1 | C18: 1 | D18: 2
A19: Anchor revenue | B19: =B18*'2 Drivers'!$B$52 -> 35000 | C19: =C18*'2 Drivers'!$B$52 -> 35000 | D19: =D18*'2 Drivers'!$B$52 -> 70000
A20: Category-exclusive partners | B20: 1 | C20: 3 | D20: 5 | E20: One per vertical: bank, CDMO, legal, cloud, insurer.
A21: Category revenue | B21: =B20*'2 Drivers'!$B$53 -> 15000 | C21: =C20*'2 Drivers'!$B$53 -> 45000 | D21: =D20*'2 Drivers'!$B$53 -> 75000
A22: Summit sponsorship | B22: =B5*'2 Drivers'!$B$54 -> 25000 | C22: =C5*'2 Drivers'!$B$54 -> 50000 | D22: =D5*'2 Drivers'!$B$54 -> 50000
A23: Summit tickets and booths | B23: 35000 | C23: 90000 | D23: 110000 | E23: WEAKEST LINE. Rebuild seat by seat before showing an investor.
A24: Event a la carte (away dinners, guest passes, public seats) | B24: 8000 | C24: 22000 | D24: 30000
A25: TOTAL REVENUE | B25: =B15+B17+B19+B21+B22+B23+B24 -> 207150 | C25: =C15+C17+C19+C21+C22+C23+C24 -> 423380 | D25: =D15+D17+D19+D21+D22+D23+D24 -> 561460
A26: COSTS
A27: Dinner delivery | B27: =B4*'2 Drivers'!$B$45*'2 Drivers'!$B$7 -> 38400 | C27: =C4*'2 Drivers'!$B$45*'2 Drivers'!$B$7 -> 64000 | D27: =D4*'2 Drivers'!$B$45*'2 Drivers'!$B$7 -> 76800
A28: Summit attendees | B28: 180 | C28: 380 | D28: 450
A29: Summit delivery | B29: =B28*'2 Drivers'!$B$8 -> 36000 | C29: =C28*'2 Drivers'!$B$8 -> 76000 | D29: =D28*'2 Drivers'!$B$8 -> 90000
A30: Welcome kits | B30: =(B8+B9)*'2 Drivers'!$B$10+B10*'2 Drivers'!$B$11 -> 4335 | C30: =(C8+C9)*'2 Drivers'!$B$10+C10*'2 Drivers'!$B$11 -> 8100 | D30: =(D8+D9)*'2 Drivers'!$B$10+D10*'2 Drivers'!$B$11 -> 9675
A31: Platform and ops | B31: =(B7+B11)*'2 Drivers'!$B$12 -> 4325 | C31: =(C7+C11)*'2 Drivers'!$B$12 -> 8750 | D31: =(D7+D11)*'2 Drivers'!$B$12 -> 11500 | E31: Guests included. They use the directory too.
A32: Cohorts | B32: ='2 Drivers'!$B$13*'2 Drivers'!$B$14 -> 1200 | C32: ='2 Drivers'!$B$13*'2 Drivers'!$B$14 -> 1200 | D32: ='2 Drivers'!$B$13*'2 Drivers'!$B$14 -> 1200 | E32: Fixed. The cheapest perk in the stack.
A33: New paying members acquired | B33: 83 | C33: 95 | D33: 75 | E33: Gross adds, after churn.
A34: Acquisition cost | B34: =B33*'2 Drivers'!$B$42 -> 18260 | C34: =C33*'2 Drivers'!$B$42 -> 20900 | D34: =D33*'2 Drivers'!$B$42 -> 16500
A35: Fixed operating costs | B35: 35000 | C35: 62000 | D35: 78000 | E35: Tools, marketing, travel, insurance, legal, accounting.
A36: Founder and team compensation | B36: 0 | C36: 60000 | D36: 130000 | E36: Nil in year one by choice. This is the honest line most models hide.
A37: TOTAL COSTS | B37: =B27+B29+B30+B31+B32+B34+B35+B36 -> 137520 | C37: =C27+C29+C30+C31+C32+C34+C35+C36 -> 300950 | D37: =D27+D29+D30+D31+D32+D34+D35+D36 -> 413675
A38: RESULT
A39: Contribution before compensation | B39: =B25-B37+B36 -> 69630 | C39: =C25-C37+C36 -> 182430 | D39: =D25-D37+D36 -> 277785
A40: NET CONTRIBUTION | B40: =B25-B37 -> 69630 | C40: =C25-C37 -> 122430 | D40: =D25-D37 -> 147785
...

Sheet 8 Scenarios
A1: Year two line | B1: Bear | C1: Base | D1: Bull | E1: Note
A2: Partner-hosted share of dinners | B2: 0.25 | C2: 0.5 | D2: 0.75 | E2: The cost lever.
A3: Blended dinner seat cost | B3: =105*(1-B2)+55*B2 -> 92.5 | C3: =105*(1-C2)+55*C2 -> 80 | D3: =105*(1-D2)+55*D2 -> 67.5 | E3: Calculated.
A4: Dinner sponsor attach rate | B4: 0.5 | C4: 0.8 | D4: 1 | E4: The revenue lever.
A5: Paying members | B5: 100 | C5: 150 | D5: 180 | E5: Bear assumes two chapters underfill.
A6: Category-exclusive partners | B6: 1 | C6: 3 | D6: 5 | E6: Bear assumes only one vertical closes.
A7: Summit tickets and booths | B7: 55000 | C7: 90000 | D7: 120000 | E7: The least evidenced line.
A8: Blended ARPU | B8: 783 | C8: 783 | D8: 783 | E8: Held constant so the scenarios test volume and sponsorship, not price.
A9: Membership revenue | B9: =B5*B8 -> 78300 | C9: =C5*C8 -> 117450 | D9: =D5*D8 -> 140940
A10: Dinner sponsorship | B10: =20*4000*B4 -> 40000 | C10: =20*4000*C4 -> 64000 | D10: =20*4000*D4 -> 80000 | E10: 20 dinners in year two.
A11: Anchor and category sponsorship | B11: =35000+B6*15000 -> 50000 | C11: =35000+C6*15000 -> 80000 | D11: =35000+D6*15000 -> 110000
A12: Summit sponsorship | B12: 50000 | C12: 50000 | D12: 50000 | E12: Two summits.
A13: Event a la carte | B13: 12000 | C13: 22000 | D13: 32000
A14: Total revenue | B14: =B9+B10+B11+B12+B7+B13 -> 285300 | C14: =C9+C10+C11+C12+C7+C13 -> 423450 | D14: =D9+D10+D11+D12+D7+D13 -> 532940
A15: Dinner delivery cost | B15: =20*40*B3 -> 74000 | C15: =20*40*C3 -> 64000 | D15: =20*40*D3 -> 54000
A16: Summit delivery cost | B16: 60000 | C16: 76000 | D16: 90000
A17: Members, kits, platform, cohorts, acquisition | B17: =B5*95 -> 9500 | C17: =C5*95 -> 14250 | D17: =D5*95 -> 17100 | E17: Blended per-member servicing and acquisition.
A18: Fixed costs and compensation | B18: 110000 | C18: 122000 | D18: 135000
A19: Total costs | B19: =B15+B16+B17+B18 -> 253500 | C19: =C15+C16+C17+C18 -> 276250 | D19: =D15+D16+D17+D18 -> 296100
A20: NET CONTRIBUTION | B20: =B14-B19 -> 31800 | C20: =C14-C19 -> 147200 | D20: =D14-D19 -> 236840
A21: Net margin | B21: =B20/B14 -> 0.11146162 | C21: =C20/C14 -> 0.34762073 | D21: =D20/D14 -> 0.44440275
A23: The bear case is the one to defend. It assumes half the dinners go unsponsored, only one category partner closes, two chapters underfill and summit revenue lands 39 percent below plan. If the bear case still clears zero, the model is not fragile.
A25: Note what is NOT flexed here: price. All three scenarios hold ARPU constant, because the risk in this business is filling rooms and closing sponsors, not whether $790 is the right number.

Sheet 9 Sensitivity
A1: TWO-WAY SENSITIVITY: annual dinner programme net cost, 20 dinners
A2: Negative means the dinner programme generates a surplus before any membership revenue.
A4: Partner-hosted share \ Sponsor per dinner | B4: $0 | C4: $2,000 | D4: $4,000 | E4: $6,000 | F4: Read
A5: 0 | B5: =20*(40*(105*(1-$A5)+55*$A5)-0) -> 84000 | C5: =20*(40*(105*(1-$A5)+55*$A5)-2000) -> 44000 | D5: =20*(40*(105*(1-$A5)+55*$A5)-4000) -> 4000 | E5: =20*(40*(105*(1-$A5)+55*$A5)-6000) -> -36000 | F5: All restaurant. The most expensive way to run this.
A6: 0.25 | B6: =20*(40*(105*(1-$A6)+55*$A6)-0) -> 74000 | C6: =20*(40*(105*(1-$A6)+55*$A6)-2000) -> 34000 | D6: =20*(40*(105*(1-$A6)+55*$A6)-4000) -> -6000 | E6: =20*(40*(105*(1-$A6)+55*$A6)-6000) -> -46000
A7: 0.5 | B7: =20*(40*(105*(1-$A7)+55*$A7)-0) -> 64000 | C7: =20*(40*(105*(1-$A7)+55*$A7)-2000) -> 24000 | D7: =20*(40*(105*(1-$A7)+55*$A7)-4000) -> -16000 | E7: =20*(40*(105*(1-$A7)+55*$A7)-6000) -> -56000 | F7: The base case.
A8: 0.75 | B8: =20*(40*(105*(1-$A8)+55*$A8)-0) -> 54000 | C8: =20*(40*(105*(1-$A8)+55*$A8)-2000) -> 14000 | D8: =20*(40*(105*(1-$A8)+55*$A8)-4000) -> -26000 | E8: =20*(40*(105*(1-$A8)+55*$A8)-6000) -> -66000
A9: 1 | B9: =20*(40*(105*(1-$A9)+55*$A9)-0) -> 44000 | C9: =20*(40*(105*(1-$A9)+55*$A9)-2000) -> 4000 | D9: =20*(40*(105*(1-$A9)+55*$A9)-4000) -> -36000 | E9: =20*(40*(105*(1-$A9)+55*$A9)-6000) -> -76000 | F9: All partner-hosted. Venue relationships are worth more than any price rise.
A11: BREAK-EVEN ON PAYING MEMBERS (year two fixed base)
A12: Line | B12: Value | F12: Note
A13: Fixed costs plus compensation | B13: 122000 | F13: From the base scenario.
A14: Sponsorship and summit contribution | B14: =(20*4000*0.8)+35000+3*15000+50000+90000-76000 -> 208000 | F14: Sponsorship and summit revenue less summit delivery.
A15: Shortfall to be covered by membership | B15: =B13-B14 -> -86000 | F15: If negative, sponsorship alone already covers the fixed base.
A16: Contribution per paying member | B16: ='3 Unit Economics'!I4 -> 580 | F16: Using the Attending tier as the marginal member.
A17: Paying members required to break even | B17: =IF(B15<=0,0,B15/B16) -> 0
A19: Read the top table first. Every row moving down and every column moving right is money the business keeps. Moving from all-restaurant unsponsored (top left) to all-partner-hosted at a $4,000 sponsor (bottom, third column) is a swing of roughly $148,000 a year on the dinner programme alone. No pricing decision in this business is worth as much as venue partnerships and sponsor attach.

Sheet 10 Investor Metrics
A1: Metric | B1: Year 1 | C1: Year 2 | D1: Year 3 | E1: Note
A2: Total revenue | B2: ='7 Three-Year Build'!B25 -> 207150 | C2: ='7 Three-Year Build'!C25 -> 423380 | D2: ='7 Three-Year Build'!D25 -> 561460
A3: Net contribution | B3: ='7 Three-Year Build'!B40 -> 69630 | C3: ='7 Three-Year Build'!C40 -> 122430 | D3: ='7 Three-Year Build'!D40 -> 147785 | E3: After all costs including compensation from year two.
A4: Net margin | B4: ='7 Three-Year Build'!B41 -> 0.33613324 | C4: ='7 Three-Year Build'!C41 -> 0.28917285 | D4: ='7 Three-Year Build'!D41 -> 0.26321555
A5: Revenue growth | B5: n/a | C5: ='7 Three-Year Build'!C25/'7 Three-Year Build'!B25-1 -> 1.043833 | D5: ='7 Three-Year Build'!D25/'7 Three-Year Build'!C25-1 -> 0.32613728
A6: Paying members | B6: ='7 Three-Year Build'!B11 -> 83 | C6: ='7 Three-Year Build'!C11 -> 150 | D6: ='7 Three-Year Build'!D11 -> 180
A7: Guest members | B7: ='7 Three-Year Build'!B7 -> 90 | C7: ='7 Three-Year Build'!C7 -> 200 | D7: ='7 Three-Year Build'!D7 -> 280 | E7: The asset that prices the sponsorship.
A8: Revenue per paying member | B8: ='7 Three-Year Build'!B42 -> 2495.7831 | C8: ='7 Three-Year Build'!C42 -> 2822.5333 | D8: ='7 Three-Year Build'!D42 -> 3119.2222 | E8: Rises without a price increase.
A9: Membership share of revenue | B9: ='7 Three-Year Build'!B43 -> 0.29133478 | C9: ='7 Three-Year Build'!C43 -> 0.27724503 | D9: ='7 Three-Year Build'!D43 -> 0.24945677
A10: Sponsorship share of revenue | B10: ='7 Three-Year Build'!B44 -> 0.50108617 | C10: ='7 Three-Year Build'!C44 -> 0.4582172 | D10: ='7 Three-Year Build'!D44 -> 0.50119332 | E10: The core of the model.
A11: Capacity utilisation | B11: ='7 Three-Year Build'!B13 -> 0.79541667 | C11: ='7 Three-Year Build'!C13 -> 0.8625 | D11: ='7 Three-Year Build'!D13 -> 0.8625 | E11: Above 90 percent needs a new chapter or a higher cadence.
A12: Chapters live | B12: ='7 Three-Year Build'!B3 -> 3 | C12: ='7 Three-Year Build'!C3 -> 5 | D12: ='7 Three-Year Build'!D3 -> 5
A13: Rooms convened | B13: ='7 Three-Year Build'!B4+'7 Three-Year Build'!B5 -> 13 | C13: ='7 Three-Year Build'!C4+'7 Three-Year Build'!C5 -> 22 | D13: ='7 Three-Year Build'!D4+'7 Three-Year Build'!D5 -> 26 | E13: Dinners plus summits.
A14: Blended LTV to CAC | B14: n/a | C14: =('4 LTV, CAC & Payback'!E3)/('4 LTV, CAC & Payback'!F3) -> 9.28 | E14: Using the Attending tier. Directional until two renewal cycles run.
A16: The metric an investor will fixate on is capacity utilisation. It is the only line that shows this business has a physical constraint, and it is the reason the expansion plan is about cities and cadence rather than a sales target.

Sheet 11 Risks & Validation
A1: Risk | B1: What breaks | C1: Severity | D1: How to validate or de-risk before it matters
A2: Retention is unproven | B2: Every LTV figure in tab 4 rests on assumed renewal rates with no history. If Resident retention is 40 percent rather than 65, LTV falls by a third. | C2: High | D2: Do not quote LTV to an investor as fact. Run two renewal cycles and report actuals. Track intent from dinner two onward.
A3: Summit revenue is the weakest line | B3: Years two and three carry $90,000 and $110,000 of summit ticket and booth revenue on a single blended assumption. | C3: High | D3: Rebuild seat by seat: pass count by type, booth count by tier, sponsor cheques. Do it before the venue is committed.
A4: Sponsor attach rate | B4: The model needs 80 percent of dinners sponsored or partner-hosted by year two. At 50 percent the dinner programme swings to a real cost. | C4: High | D4: Sell the first four dinner sponsors before scaling the calendar. Treat an unsponsored dinner as a decision not to hold one.
A5: Capacity ceiling misread as a growth problem | B5: Pressure to sell more memberships into a full chapter degrades composition, which is the entire asset. | C5: High | D5: Hold the ceiling. Open a waitlist and use it as sponsorship proof. Add cities or cadence, never seats.
A6: Guest supply | B6: If guests do not come, paying members leave. The free side is the product. | C6: High | D6: Track guest-to-payer ratio every dinner. Below 1.2 to 1, pause paid acquisition and recruit guests.
A7: Founder concentration | B7: Curation, seating, introductions and sponsor selling all sit with one person. This is the binding operational constraint well before capital is. | C7: High | D7: Chapter hosts by year two. Document the composition method so it is transferable.
A8: Category partner ladder | B8: Year three assumes five category partners at $15,000. Only one exists in the plan today. | C8: Medium | D8: Close one, publish the composition report it buys, then use it to sell the second.
A9: Venue cost inflation | B9: The blended $80 seat assumes half of dinners are partner-hosted. Restaurant-only pushes it to $105. | C9: Medium | D9: Sign two venue partners per chapter before the chapter opens.
A10: Tax and registration | B10: GST/HST registration is required once revenue crosses $30,000 in four quarters. Year one crosses it immediately. | C10: Medium | D10: Register before the first membership is sold. Separate QST registration for Quebec.
A11: Price is too low | B11: LTV to CAC above 7 on every tier suggests conservative pricing rather than exceptional economics. | C11: Low | D11: Hold prices through year one to buy proof, then test Attending upward at the first renewal.
A13: The four High severity risks share one root: this model projects a business that has not yet held its first dinner. Every number here is a hypothesis with arithmetic attached. Present it that way and it is credible. Present it as a forecast and it is not.
