Workbook

Sheet 1 Strategy
A1: Decision | B1: Choice | C1: Rationale
A2: Goal balance | B2: Delight-weighted at entry, yield-weighted at the top | C2: The entry tier must feel obviously worth it to a bootstrapped founder or a curious clinician. Yield is captured at Attending and Chief, where exhibiting and national access carry real budget.
A3: Stage (When) | B3: Pre-launch to MVP | C3: No attendance history yet. Price for learning and commitment, not for maximum extraction. Founding rates lock early believers and buy proof.
A4: Beachhead (Who) | B4: GTA health tech founders, seed to Series B, plus GTA clinicians as hosted guests | C4: Easy to service (one city, one dinner cadence), zero incumbent share in curated cross-group rooms, and the group whose pain (18 months for one clinical conversation) is sharpest.
A5: Sales motion | B5: Gathering at Guest and Resident, Farming at Attending, Hunting at Chief and Partnership | C5: Free and $290 must be self-serve through the existing apply flow. Attending converts through the dinner experience. Chief and category partnership are conversations.
A6: Strategic intent | B6: Differentiate | C6: MaRS, OBIO, CAN Health and Medtech Canada all connect this ecosystem through programs and projects. None sells a composed, balanced, intimate room. Do not follow association dues conventions; set a room-time convention instead.
A7: Denominator | B7: Per member, per year | C7: Value is delivered in seats at rooms, and rooms happen on an annual cadence (4 dinners plus a summit). A per-seat or per-event denominator would price attendance and destroy the belonging story. Annual also matches the composition planning cycle.
A8: Pricing basis | B8: Value-based, floored by event cost | C8: Price is set from the value of guaranteed proximity and the redeemable rate card, then checked against the real cost of a dinner seat. Cost-based alone would undercharge; market-based alone would anchor to association dues, which buy far less room time.
A9: Denominator x basis fit | B9: Pass | C9: Per-member x value-based is a clean pair. The risk with per-member pricing (decoupling from value) is handled by the member rate card, which lets heavy users redeem more and light users still feel the fee is fair.
A10: Deviation from the framework | B10: Decoy share is intentionally high | C10: The standard split is Decoy 5-20 / Hero 60-80 / Anchor 5-20. Here the planning split is Resident 45 / Attending 40 / Chief 15 of paying members. In an events business the entry tier carries genuine recurring value (four real dinners), unlike a software Lite plan. Watch the ratio: if Resident exceeds 60 percent after two quarters, Attending is underbuilt, not overpriced.
A11: The one non-negotiable | B11: Guest is free forever | C11: Clinicians, researchers, academics, students and policy leaders create the value that every paying tier is buying proximity to. Charging them, even a token amount, collapses the asset. This is a permanent design rule, not a launch promotion.

Sheet 2 Perk Matrix
A1: Perk / capability | B1: Market demand | C1: Competitive density | D1: Zone | E1: Packaging role | F1: Marketing label | G1: Assigned tier | H1: Cost to deliver, per member per year
A2: Directory profile with protected pitch media | B2: Most | C2: A few do this | D2: Differentiator | E2: Freemium-Lite | F2: Leading | G2: Guest+ | H2: $0, already built
A3: Nomination rights (nominate a clinician or researcher) | B3: Some | C3: Only we do this | D3: Niche | E3: Freemium-Lite | F3: Innovation | G3: Guest+ | H3: $0, and it is the acquisition engine
A4: Invitation to dinners when composition calls for you | B4: All | C4: Only we do this | D4: Differentiator | E4: Freemium-Lite | F4: Leading | G4: Guest | H4: Seat cost when redeemed
A5: Live online cohorts, attend and speak on panels | B5: Most | C5: Most do this | D5: Table stakes | E5: Freemium-Lite | F5: Commoditized | G5: Guest+ | H5: $0 marginal
A6: Newsletter and annual composition report | B6: Most | C6: A few do this | D6: Differentiator | E6: Freemium-Lite | F6: Leading | G6: Guest+ | H6: $0
A7: Digital verified member badge for LinkedIn | B7: Some | C7: Most do this | D7: Noise | E7: Freemium-Lite | F7: Commoditized | G7: Guest+ | H7: $0
A8: Guaranteed seat at every home-province dinner | B8: All | C8: Only we do this | D8: Differentiator | E8: Premium-Hero | F8: Leading | G8: Resident+ | H8: Seat cost x 4
A9: Recorded cohort library | B9: Most | C9: Most do this | D9: Table stakes | E9: Freemium-Lite | F9: Commoditized | G9: Resident+ | H9: $0 marginal
A10: Physical member card, presented at the table | B10: Some | C10: A few do this | D10: Niche | E10: Premium-Hero | F10: Innovation | G10: Resident+ | H10: $12
A11: Welcome kit (card, notebook, pin, luggage tag) | B11: Some | C11: Most do this | D11: Noise | E11: Freemium-Lite | F11: Commoditized | G11: Resident+ | H11: $45
A12: Member rate on the summit pass | B12: All | C12: Most do this | D12: Table stakes | E12: Premium-Hero | F12: Commoditized | G12: Resident+ | H12: Margin give, not cash
... A31: Founding member price lock, first 100 paid members | B31: Most | C31: A few do this | D31: Differentiator | E31: Premium-Hero | F31: Leading | G31: All paid | H31: Margin give, permanent
A33: Fourteen of the thirty perks cost nothing marginal to deliver. That is how the value stack reaches 4-5x the fee without eroding margin. The partner benefits bundle is the single strongest line: it is funded by category partners and can exceed the membership fee on its own.

Sheet 3 Pricing Model
A1: BOTTOM-UP PRICING MODEL, CAD, ALL FIGURES EXCLUDE GST/HST/QST
A3: BLOCK A. UNIT COST ASSUMPTIONS (blue cells are editable inputs)
A4: Dinner seat cost, restaurant format (TO/VAN benchmark) | B4: 105 | F4: Assumption: 3 courses, venue minimum, service, no alcohol.
A5: Dinner seat cost, partner-hosted format (donated venue, catered) | B5: 55 | F5: Assumption: partner boardroom or office, catering only.
A6: Share of dinners that are partner-hosted | B6: 0.5 | F6: Assumption. This is the single biggest cost lever in the model.
A7: Blended dinner seat cost | B7: =B4*(1-B6)+B5*B6 -> 80 | F7: Formula. Drives every redemption calculation.
A8: Summit cost per attendee | B8: 200 | F8: Assumption: venue, AV, catering, staffing at 150-250 attendees.
A9: Exhibitor booth servicing cost | B9: 400 | F9: Assumption: floor space, table, power, listing.
A10: Welcome kit cost, standard | B10: 45 | F10: Card, notebook, pin, luggage tag.
A11: Welcome kit cost, Chief | B11: 120 | F11: Full kit plus printed materials.
A12: Platform and ops cost, per member per year | B12: 25 | F12: Supabase, Vercel, Resend, admin time allocation.
A13: Cohort session cost | B13: 150 | F13: Editing and hosting. 8 sessions per year, fixed not per member.
A15: BLOCK B. PUBLIC RATE CARD (what a non-member pays)
A16: Public dinner ticket | B16: 70 | F16: Set below true cost on purpose. Sponsors close the gap.
A17: Public summit day pass | B17: 395
A18: Public summit exhibitor booth | B18: 2500
A20: BLOCK C. COST-TO-SERVICE FLOOR FOR THE HERO TIER (Attending)
A21: Target gross margin for an events business | B21: 0.6 | F21: Assumption. Events do not reach software margins. 60 percent is the working target.
A22: Typical-redemption cost to service, dinners UNSPONSORED | B22: =B7*2.3+B7*0.6+B8*0.7+B10+B12 -> 442 | F22: 2.3 of 4 home dinners, 0.6 of 2 away dinners, 0.7 summit, kit, platform.
A23: Floor price at target margin, UNSPONSORED | B23: =B22/(1-B21) -> 1105 | F23: FINDING: the Hero price of $790 sits below this floor. See Block G.
A24: Typical-redemption cost to service, dinners SPONSORED | B24: =B8*0.7+B10+B12 -> 210 | F24: Sponsor or donated venue covers dinner food and room.
A25: Floor price at target margin, SPONSORED | B25: =B24/(1-B21) -> 525 | F25: The Hero clears this comfortably.
A27: BLOCK D. MARKET BAND (normalized to an annual individual membership)
A28: Market low, chamber of commerce style individual dues | B28: 400 | F28: Assumption, to confirm.
A29: Market median, industry association individual membership | B29: 950 | F29: Assumption, to confirm against OBIO and Medtech Canada published rates.
A30: Market high, curated peer network annual seat | B30: 3500 | F30: Assumption, to confirm.
A31: One conference pass alone, for comparison | B31: 395 | F31: A single day, no relationships, no follow-up.
A33: BLOCK E. VALUE CEILING FOR THE HERO TIER (Attending)
A34: Four home-province dinners at the public rate | B34: =B16*4 -> 280
A35: Two out-of-province dinners at the public rate | B35: =B16*2 -> 140
A36: Summit day pass at the public rate | B36: =B17 -> 395
A37: Exhibitor booth saving if used (public minus member rate) | B37: =B18-1450 -> 1050
A38: Cohort library, directory, introductions | B38: 200 | F38: Assumption, conservative.
A39: Partner benefits bundle (cloud credits, legal hour, banking offer) | B39: 2000 | F39: Assumption. Funded by category partners, zero cost to us.
A40: Total quantified annual value | B40: =SUM(B34:B39) -> 4065 | F40: Formula.
A41: Capture fraction actually taken | B41: =B49/B40 -> 0.19434194 | F41: Formula. Healthy range is 0.10 to 0.30.
A43: BLOCK F. THE LADDER (Hero set first, Decoy and Anchor derived)
A44: Tier | B44: Annual price | C44: Monthly price | D44: Ratio to Hero | E44: Role | F44: Note
A45: Guest | B45: 0 | D45: =B45/$B$47 -> 0 | E45: Freemium | F45: Free forever. Not a commercial tier, it is the magnet.
A46: Resident | B46: 290 | C46: 29 | D46: =B46/$B$47 -> 0.36708861 | E46: Decoy | F46: Entry. Priced at roughly what four dinner tickets cost.
...

Sheet 4 Pricing Table
B1: Guest | C1: Resident | D1: Attending | E1: Chief
A2: Plan name | B2: Guest | C2: Resident | D2: Attending | E2: Chief
A3: Role | B3: Freemium | C3: Decoy | D3: HERO | E3: Anchor
A4: Flag | D4: Most popular
A5: Who it is for | B5: Clinicians, researchers, academics, students and policy leaders. Anyone giving value to the room rather than selling into it. | C5: Bootstrapped founders, solo operators, and clinicians who want a guaranteed seat in their own province. | D5: Funded startups and operators working nationally, and anyone exhibiting at the summit. | E5: Scale-ups and firms that want every room in the country and a presence at both summits.
A6: Denominator | B6: Per member, per year | C6: Per member, per year | D6: Per member, per year | E6: Per member, per year
A7: Annual price (CAD, tax excl.) | B7: $0 forever | C7: $290 | D7: $790 | E7: $2,950
A8: Monthly option | B8: n/a | C8: $29 | D8: $79 | E8: Annual only
A9: Founding rate, first 100 paid members | B9: n/a | C9: $240 locked for life | D9: $650 locked for life | E9: $2,450 locked for life
A10: Call to action | B10: Request an invitation | C10: Join as a Resident | D10: Join as an Attending | E10: Talk to us about Chief
A12: ROOMS
A13: Home-province quarterly dinners | B13: Invited when the room needs you | C13: Included, all 4 | D13: Included, all 4 | E13: Included, all 4
A14: Out-of-province dinners | B14: Invited | C14: Member rate $35 | D14: 2 included, then $35 | E14: Included, every city
A15: Summit day pass | B15: Invited, hosted | C15: Member rate $195 | D15: Included | E15: Included, both cities
A16: Summit exhibitor booth | B16: n/a | C16: Member rate $1,900 | D16: Member rate $1,450 | E16: Included, 2nd booth $900
A17: Guest pass for a colleague | B17: n/a | C17: Member rate $45 | D17: 1 per year free | E17: 3 per year free
A19: ONLINE
A20: Live cohorts and panels | B20: Yes | C20: Yes | D20: Yes | E20: Yes
A21: Recorded cohort library | B21: No | C21: Yes | D21: Yes | E21: Yes
A22: Moderate a cohort | B22: No | C22: No | D22: Yes | E22: Yes
A23: Propose a cohort topic | B23: No | C23: Yes | D23: Yes | E23: Yes
A25: NETWORK
A26: Directory profile with pitch media | B26: Yes | C26: Yes | D26: Yes | E26: Yes
A27: Nominate a clinician or researcher | B27: Yes | C27: Yes | D27: Yes | E27: Yes
A28: Introduction requests | B28: On request | C28: 2 per quarter | D28: Unlimited, fair use | E28: Unlimited, fair use
A29: Seat-preference request | B29: No | C29: Yes | D29: Yes | E29: Yes
A30: Partner benefits bundle | B30: No | C30: Yes | D30: Yes | E30: Yes
A32: STATUS AND STAGE
A33: Digital member badge | B33: Yes | C33: Yes | D33: Yes | E33: Yes
A34: Physical member card | B34: No | C34: Yes | D34: Yes | E34: Yes
A35: Welcome kit | B35: Card only | C35: Yes | D35: Yes, plus summit pack | E35: Full kit
A36: Printables and merch allocation | B36: No | C36: No | D36: No | E36: $250 credit
A37: Summit speaking consideration | B37: Eligible | C37: Eligible | D37: Priority | E37: Priority
A38: Co-host a dinner in your city | B38: No | C38: No | D38: No | E38: Yes
A39: Input on the summit programme | B39: No | C39: No | D39: No | E39: Yes
A40: Member wall listing | B40: No | C40: No | D40: No | E40: Yes
A42: Annual composition report | B42: Yes | C42: Yes | D42: Yes | E42: Yes
A43: Early access to dates and tickets | B43: No | C43: Yes | D43: Yes | E43: Yes
A45: All prices exclude GST/HST/QST. Every seat, at every tier including Chief, remains subject to composition: a room needs its balance of builders and validators, and no tier can displace that. State this in the terms.

Sheet 5 Member Rate Card
A1: Item | B1: Public rate | C1: Guest | D1: Resident | E1: Attending | F1: Chief | G1: Deepest saving versus public
A2: Quarterly dinner, home province | B2: $70 | C2: $0, hosted | D2: Included | E2: Included | F2: Included | G2: $280 per year
A3: Quarterly dinner, other province | B3: $70 | C3: $0, hosted | D3: $35 | E3: 2 included, then $35 | F3: Included | G3: $1,120 if all cities
A4: Summit day pass | B4: $395 | C4: $0, hosted | D4: $195 | E4: Included | F4: Included, both cities | G4: $790 for two passes
A5: Summit exhibitor booth | B5: $2,500 | C5: n/a | D5: $1,900 | E5: $1,450 | F5: Included, 2nd at $900 | G5: $2,500 on the first booth
A6: Guest pass for a colleague | B6: $70 | C6: n/a | D6: $45 | E6: 1 free, then $45 | F6: 3 free, then $45 | G6: $210
A7: Cohort recordings | B7: not sold | C7: no | D7: yes | E7: yes | F7: yes | G7: n/a
A8: Printables and merch | B8: retail | C8: n/a | D8: retail | E8: retail | F8: $250 credit | G8: $250
A11: The member rate is the whole mechanism. Low-ticket items (dinners) are included outright because inclusion drives attendance and attendance is the product. High-ticket items (summit, booth) are discounted rather than included, so heavy commercial users still contribute revenue in proportion to what they extract.

Sheet 6 Redemption & Margin
A1: Tier | B1: Annual fee | C1: Dinners available | D1: Dinners, typical | E1: Dinners, full | F1: Summits, typical | G1: Cost TYPICAL, unsponsored | H1: Margin TYPICAL, unsponsored | I1: Cost FULL, unsponsored | J1: Margin FULL, unsponsored | K1: Cost TYPICAL, sponsored | L1: Margin TYPICAL, sponsored
A11: Guest | B11: 0 | C11: invite only | D11: 1.5 | E11: 2 | F11: 0.5 | G11: =D11*'3 Pricing Model'!$B$7+F11*'3 Pricing Model'!$B$8+0+'3 Pricing Model'!$B$12 -> 245 | H11: =IF(B11=0,"n/a, this is the investment",(B11-G11)/B11) -> n/a, this is the investment | I11: =E11*'3 Pricing Model'!$B$7+F11*'3 Pricing Model'!$B$8+0+'3 Pricing Model'!$B$12 -> 285 | J11: =IF(B11=0,"n/a",(B11-I11)/B11) -> n/a | K11: =F11*'3 Pricing Model'!$B$8+0+'3 Pricing Model'!$B$12 -> 125 | L11: =IF(B11=0,"n/a",(B11-K11)/B11) -> n/a
A12: Resident | B12: 290 | C12: 4 | D12: 2.3 | E12: 4 | F12: 0 | G12: =D12*'3 Pricing Model'!$B$7+F12*'3 Pricing Model'!$B$8+'3 Pricing Model'!$B$10+'3 Pricing Model'!$B$12 -> 254 | H12: =IF(B12=0,"n/a, this is the investment",(B12-G12)/B12) -> 0.12413793 | I12: =E12*'3 Pricing Model'!$B$7+F12*'3 Pricing Model'!$B$8+'3 Pricing Model'!$B$10+'3 Pricing Model'!$B$12 -> 390 | J12: =IF(B12=0,"n/a",(B12-I12)/B12) -> -0.34482759 | K12: =F12*'3 Pricing Model'!$B$8+'3 Pricing Model'!$B$10+'3 Pricing Model'!$B$12 -> 70 | L12: =IF(B12=0,"n/a",(B12-K12)/B12) -> 0.75862069
A13: Attending | B13: 790 | C13: 6 | D13: 2.9 | E13: 6 | F13: 0.7 | G13: =D13*'3 Pricing Model'!$B$7+F13*'3 Pricing Model'!$B$8+'3 Pricing Model'!$B$10+'3 Pricing Model'!$B$12 -> 442 | H13: =IF(B13=0,"n/a, this is the investment",(B13-G13)/B13) -> 0.44050633 | I13: =E13*'3 Pricing Model'!$B$7+F13*'3 Pricing Model'!$B$8+'3 Pricing Model'!$B$10+'3 Pricing Model'!$B$12 -> 690 | J13: =IF(B13=0,"n/a",(B13-I13)/B13) -> 0.12658228 | K13: =F13*'3 Pricing Model'!$B$8+'3 Pricing Model'!$B$10+'3 Pricing Model'!$B$12 -> 210 | L13: =IF(B13=0,"n/a",(B13-K13)/B13) -> 0.73417722
A14: Chief | B14: 2950 | C14: 20 | D14: 6 | E14: 10 | F14: 1.5 | G14: =D14*'3 Pricing Model'!$B$7+F14*'3 Pricing Model'!$B$8+'3 Pricing Model'!$B$11+'3 Pricing Model'!$B$12+'3 Pricing Model'!$B$9 -> 1325 | H14: =IF(B14=0,"n/a, this is the investment",(B14-G14)/B14) -> 0.55084746 | I14: =E14*'3 Pricing Model'!$B$7+F14*'3 Pricing Model'!$B$8+'3 Pricing Model'!$B$11+'3 Pricing Model'!$B$12+'3 Pricing Model'!$B$9 -> 1645 | J14: =IF(B14=0,"n/a",(B14-I14)/B14) -> 0.44237288 | K14: =F14*'3 Pricing Model'!$B$8+'3 Pricing Model'!$B$11+'3 Pricing Model'!$B$12+'3 Pricing Model'!$B$9 -> 845 | L14: =IF(B14=0,"n/a",(B14-K14)/B14) -> 0.71355932
A16: Read the two right-hand columns first. With sponsored or partner-hosted dinners every paid tier clears a healthy margin even at full redemption. With unsponsored dinners, Resident goes negative at full redemption and Attending runs on a thin line. Guest cost is not a loss, it is the cost of the gravity that makes every other tier sellable.
A18: Typical redemption assumptions: a member attends 2.3 of 4 quarterly dinners in their own city, Attending members add 0.6 away dinners, 70 percent of included summit passes are used, Chief members attend 6 dinners nationally. Adjust these directly in columns D to F and every margin recalculates.

Sheet 7 Savings Scenarios
A1: Scenario | B1: What they do in a year | C1: Cost the public way | D1: Cost as a member | E1: Membership fee | F1: Total member outlay | G1: They save | H1: Saving %
A2: Toronto bootstrapped founder, Resident | B2: 4 Toronto dinners, attends the summit, no booth | C2: =4*70+395 -> 675 | D2: =195 -> 195 | E2: =290 -> 290 | F2: =D2+E2 -> 485 | G2: =C2-F2 -> 190 | H2: =G2/C2 -> 0.28148148
A3: Montreal founder exhibiting, Attending | B3: 4 Montreal dinners, 2 Toronto dinners, summit, one booth | C3: =4*70+2*70+395+2500 -> 3315 | D3: =1450 -> 1450 | E3: =790 -> 790 | F3: =D3+E3 -> 2240 | G3: =C3-F3 -> 1075 | H3: =G3/C3 -> 0.32428356
A4: Vancouver scale-up, Chief | B4: 8 dinners across cities, both summits, booth in Toronto and Vancouver | C4: =8*70+2*395+2*2500 -> 6350 | D4: =900 -> 900 | E4: =2950 -> 2950 | F4: =D4+E4 -> 3850 | G4: =C4-F4 -> 2500 | H4: =G4/C4 -> 0.39370079
A5: Toronto physician, Guest | B5: 2 dinners as an invited guest, attends the summit | C5: =2*70+395 -> 535 | D5: =0 -> 0 | E5: =0 -> 0 | F5: =D5+E5 -> 0 | G5: =C5-F5 -> 535 | H5: =G5/C5 -> 1
A6: Clinician who upgrades, Resident | B6: 4 dinners in her province, summit, brings a colleague once | C6: =4*70+395+70 -> 745 | D6: =195+45 -> 240 | E6: =290 -> 290 | F6: =D6+E6 -> 530 | G6: =C6-F6 -> 215 | H6: =G6/C6 -> 0.2885906
A8: The Resident story is the cleanest one for the landing page: four dinner tickets at the door cost $280. Membership is $290 and includes all four, plus the cohorts, the directory, the introductions, the partner benefits and a member rate on everything else. You are paying the price of the dinners you were already going to attend and getting the rest of the network free.
A10: The Guest row is the one to show clinicians. They receive $535 of access and pay nothing, permanently, because their presence is what the paying tiers are buying proximity to.

Sheet 8 Year One Model
A1: Line | B1: Count / value | C1: Notes
A2: Guest members (free) | B2: 90 | C2: Blue cells are your planning inputs. Hold roughly 1.5 guests per paying member or composition breaks.
A3: Resident members | B3: 45 | C3: 45 percent of paying members.
A4: Attending members | B4: 30 | C4: 40 percent of paying members. This is the tier to push.
A5: Chief members | B5: 8 | C5: 15 percent of paying members.
A6: Total paying members | B6: =SUM(B3:B5) -> 83 | C6: Formula. Launch-year volumes, not steady state.
A7: Membership revenue | B7: =B3*290+B4*790+B5*2950 -> 60350 | C7: Formula against the ladder in tab 3.
A8: Dinners run in the year | B8: 12 | C8: Ramped, not 20. Toronto quarterly from Q1, two more cities from mid-year.
A9: Average seats filled per dinner | B9: 40
A10: Total dinner seats delivered | B10: =B8*B9 -> 480 | C10: Formula.
A11: Dinner delivery cost at the blended seat rate | B11: =B10*'3 Pricing Model'!$B$7 -> 38400 | C11: Formula.
A12: Per-dinner sponsorship needed to cover food | B12: =B11/B8 -> 3200 | C12: Formula. Compare against the $3,000 to $7,500 per-dinner band. Landing inside it means one sponsor funds one dinner.
A13: Summit attendees, one summit in year one | B13: 180 | C13: Toronto only in year one. Vancouver joins in year two.
A14: Summit delivery cost | B14: =B13*'3 Pricing Model'!$B$8 -> 36000 | C14: Formula.
A15: Summit ticket and booth revenue | B15: 35000 | C15: Assumption. Rebuild seat by seat once the venue is chosen.
A16: Membership revenue net of kits and platform | B16: =B7-(B3+B4)*'3 Pricing Model'!$B$10-B5*'3 Pricing Model'!$B$11-B6*'3 Pricing Model'!$B$12 -> 53940 | C16: Formula.
A17: Programme surplus before any sponsorship | B17: =B15+B16-B11-B14 -> 14540 | C17: Formula. Positive is a surplus, negative is the gap sponsorship must close.
A18: Sponsorship secured (anchor, category, per dinner) | B18: 60000 | C18: Assumption: one anchor at the low end plus two category partners.
A19: Year one contribution after sponsorship | B19: =B17+B18 -> 74540 | C19: Formula. This is the number that funds year two.
A21: Two findings to read here. First, the per-dinner sponsorship figure in row 12 lands inside the band already in the business model, so one sponsor funds one dinner cleanly. Second, at these launch volumes the programme is close to self-funding before sponsorship, which means sponsorship money is growth capital rather than survival money. Push the member counts down by half and re-read row 17 to see the pessimistic case.

Sheet 9 Tier Names
A1: Set | B1: Free tier | C1: Entry paid | D1: Hero | E1: Anchor | F1: Why it works | G1: Watch out for
A2: A. Clinical ladder (RECOMMENDED) | B2: Guest | C2: Resident | D2: Attending | E2: Chief | F2: It borrows the hospital career ladder, so every clinician reads the hierarchy instantly, and Attending is a genuine double meaning: the senior clinical rank and the person who attends. Uniquely medtech, impossible to confuse with a software plan, and it flatters the audience you most need in the room. | G2: A founder holding the title Attending could feel like appropriation to some physicians. Test it with three clinicians before committing.
A3: B. The table | B3: Guest | C3: Seat | D3: Table | E3: Host | F3: Sits directly on the brand language already built into the site and the keynote: room, table, seat, composition. Safest option, zero interpretation risk, and Host is a genuinely aspirational top tier because it comes with co-hosting rights. | G3: Less distinctive. Seat and Table are close enough in meaning that the ladder is not self-evident from the names alone.
A4: C. Scope | B4: Guest | C4: Chapter | D4: National | E4: Founding Circle | F4: The names describe exactly what you get: your local chapter, the whole country, the inner circle. Nothing to explain on the pricing page. | G4: Functional rather than memorable. It reads like a telecom plan and gives up the brand texture.
A6: Recommendation: Set A, with Set B as the fallback if the clinician test comes back uneasy. Whichever you pick, keep Guest as the free tier name in all three. It is the single most important word in the pricing page because it frames free as hosted status rather than as a discount.

Sheet 10 Tax & Terms
A1: Item | B1: Position | C1: Detail
A2: Tax treatment | B2: All prices are tax exclusive | C2: Display every price as "CAD, plus applicable taxes". Sales tax is charged at the rate of the province where the member is located, not where the dinner is held.
A3: Ontario | B3: 13% HST | C3: A $790 Attending membership bills at $892.70.
A4: British Columbia | B4: 5% GST | C4: $790 bills at $829.50. Confirm whether BC PST applies to a membership of this type.
A5: Alberta | B5: 5% GST | C5: $790 bills at $829.50.
A6: Quebec | B6: 5% GST + 9.975% QST | C6: $790 bills at $908.30. Quebec requires separate QST registration.
A7: Registration threshold | B7: Register before you cross it | C7: The small supplier threshold is $30,000 in taxable revenue across four consecutive calendar quarters. This model crosses it in the first year, so register for a GST/HST number before the first membership is sold rather than backdating later.
A8: Event tickets | B8: Taxable the same way | C8: Dinner tickets, summit passes and exhibitor booths all carry tax at the buyer province rate.
A9: Not tax advice | B9: Confirm with an accountant | C9: Rates and the treatment of memberships versus event admissions should be confirmed with a Canadian accountant before the pricing page goes live.
A11: Monthly membership guard | B11: 60 day qualifying period | C11: A monthly member becomes eligible for an included dinner seat after 60 days of continuous membership, or pays the $35 member rate before that. Without this rule someone joins for $29, takes a $70 seat, and cancels.
A12: Composition clause | B12: Seats are always subject to balance | C12: State plainly in the terms: every seat at every tier, including Chief, is subject to the composition of the room. If a dinner needs clinicians in the remaining seats, no membership tier overrides that. This protects the product and naturally caps redemption.
A13: Guest eligibility | B13: No commercial product or service | C13: Guest is for people who do not sell into this ecosystem. If a Guest founds a company or joins a vendor, they move to a paid tier at the next renewal, with a 90 day grace period. Review at application, not by self-declaration.
... A16: Founding rate | B16: First 100 paid members, locked for life | C16: Creates urgency at launch and rewards the people who joined before there was proof. Honour the lock permanently, including through future price rises.

Sheet 11 Implementation
A1: Area | B1: What to build | C1: Where it goes in the existing repo
A2: Tier field | B2: Add tier (guest | resident | attending | chief), tier_started_at, tier_renews_at, founding_rate boolean | C2: New migration 0008, or the existing attributes jsonb on members if you want to avoid a schema change first
A3: Eligibility rule | B3: Map member_type to tier eligibility: Physician, Dentist, Pharmacist, Nurse/Allied Health, Researcher/Academic, Policy/Government and Student are Guest eligible. Founder/Operator, Investor, Corporate/Strategic and Service Provider require a paid tier | C3: lib/directory/taxonomy.ts, alongside fieldsForType and requiredKeysForType
A4: Dual-role edge case | B4: A physician who is also a founder (is_founder true) pays for the venture but keeps hosted seating when attending in a clinical capacity. Store the reason in attributes.tier_source | C4: lib/directory/record.ts, in buildMemberRecord
A5: Seat ledger | B5: Track redemption per member per year: dinners_redeemed, summit_redeemed, guest_passes_used. This is what makes the margin model real instead of theoretical | C5: New table memberships_redemption, or attributes jsonb for the first two quarters
A6: Rate card enforcement | B6: Price a dinner or summit seat by looking up tier, then applying the rate card in tab 5 | C6: New lib/pricing/rate-card.ts, single source of truth
A7: Admin view | B7: Show tier, renewal date and seats redeemed on each member row so composition and margin are visible at a glance | C7: app/admin/AdminClient.tsx
A8: Pricing page | B8: Render tab 4 as the public pricing table with the Attending column flagged | C8: New app/membership/page.tsx, reusing the existing --mn-* tokens
A9: Payments | B9: Not yet built. Stripe with annual and monthly prices, plus the 60 day guard on monthly dinner eligibility | C9: Backlog item, after migration 0007 is run
A10: Blocker unchanged | B10: Migration 0007_expand_member_metadata.sql still needs to run in Supabase before any of this | C10: Noted in the handoff as the outstanding action
